2025-03-02 23:44:15,250 INFO    MainThread:533872 [wandb_setup.py:_flush():76] Current SDK version is 0.16.1
2025-03-02 23:44:15,250 INFO    MainThread:533872 [wandb_setup.py:_flush():76] Configure stats pid to 533872
2025-03-02 23:44:15,250 INFO    MainThread:533872 [wandb_setup.py:_flush():76] Loading settings from /home/ubuntu/.config/wandb/settings
2025-03-02 23:44:15,250 INFO    MainThread:533872 [wandb_setup.py:_flush():76] Loading settings from /home/ubuntu/LNS2-RL/wandb/settings
2025-03-02 23:44:15,250 INFO    MainThread:533872 [wandb_setup.py:_flush():76] Loading settings from environment variables: {}
2025-03-02 23:44:15,251 INFO    MainThread:533872 [wandb_setup.py:_flush():76] Applying setup settings: {'_disable_service': False}
2025-03-02 23:44:15,251 INFO    MainThread:533872 [wandb_setup.py:_flush():76] Inferring run settings from compute environment: {'program_relpath': 'driver.py', 'program_abspath': '/home/ubuntu/LNS2-RL/driver.py', 'program': '/home/ubuntu/LNS2-RL/driver.py'}
2025-03-02 23:44:15,251 INFO    MainThread:533872 [wandb_init.py:_log_setup():524] Logging user logs to /home/ubuntu/LNS2-RL/wandb/run-20250302_234415-840zuzvw/logs/debug.log
2025-03-02 23:44:15,251 INFO    MainThread:533872 [wandb_init.py:_log_setup():525] Logging internal logs to /home/ubuntu/LNS2-RL/wandb/run-20250302_234415-840zuzvw/logs/debug-internal.log
2025-03-02 23:44:15,251 INFO    MainThread:533872 [wandb_init.py:init():564] calling init triggers
2025-03-02 23:44:15,251 INFO    MainThread:533872 [wandb_init.py:init():571] wandb.init called with sweep_config: {}
config: {'LOCAL_N_AGENTS': 8, 'GLOBAL_N_AGENT': (0.6, 0.65, 0.7), 'N_ACTIONS': 5, 'EPISODE_LEN': [356, 356, 356], 'FOV_SIZE': 9, 'WORLD_SIZE': [10, 25, 50], 'OBSTACLE_PROB': (0.15, 0.175, 0.2), 'ACTION_COST': -0.6, 'IDLE_COST': -0.6, 'GOAL_REWARD': 0.0, 'AG_COLLISION_COST': -1.5, 'DY_COLLISION_COST': -1.5, 'NUM_TIME_SLICE': 9, 'lr': 1e-05, 'GAMMA': 0.95, 'LAM': 0.95, 'CLIPRANGE': 0.2, 'MAX_GRAD_NORM': 50, 'ENTROPY_COEF': 0.01, 'VALUE_COEF': 0.5, 'POLICY_COEF': 1, 'VALID_COEF': 0.5, 'N_EPOCHS': 10, 'N_ENVS': 32, 'N_MAX_STEPS': 70000000.0, 'N_STEPS': 256, 'MINIBATCH_SIZE': 512, 'NET_SIZE': 512, 'NUM_CHANNEL': 31, 'GOAL_REPR_SIZE': 32, 'VECTOR_LEN': 8, 'SEED': 1234, 'USE_GPU_LOCAL': False, 'USE_GPU_GLOBAL': True, 'NUM_GPU': 1, 'RETRAIN': False, 'WANDB': True, 'ENTITY': 'your_name', 'TIME': '02-03-252344', 'EXPERIMENT_PROJECT': 'MAPF', 'EXPERIMENT_NAME': 'second_stage', 'EXPERIMENT_NOTE': '', 'SAVE_INTERVAL': 1638400, 'MODEL_PATH': './models/MAPF/second_stage02-03-252344'}
2025-03-02 23:44:15,251 INFO    MainThread:533872 [wandb_init.py:init():614] starting backend
2025-03-02 23:44:15,251 INFO    MainThread:533872 [wandb_init.py:init():618] setting up manager
2025-03-02 23:44:15,257 INFO    MainThread:533872 [backend.py:_multiprocessing_setup():105] multiprocessing start_methods=fork,spawn,forkserver, using: spawn
2025-03-02 23:44:15,258 INFO    MainThread:533872 [wandb_init.py:init():624] backend started and connected
2025-03-02 23:44:15,263 INFO    MainThread:533872 [wandb_init.py:init():716] updated telemetry
2025-03-02 23:44:15,267 INFO    MainThread:533872 [wandb_init.py:init():749] communicating run to backend with 90.0 second timeout
2025-03-02 23:44:15,725 ERROR   MainThread:533872 [wandb_init.py:init():775] encountered error: It appears that you do not have permission to access the requested resource. Please reach out to the project owner to grant you access. If you have the correct permissions, verify that there are no issues with your networking setup.(Error 404: Not Found)
2025-03-02 23:44:15,810 ERROR   MainThread:533872 [wandb_init.py:init():1188] It appears that you do not have permission to access the requested resource. Please reach out to the project owner to grant you access. If you have the correct permissions, verify that there are no issues with your networking setup.(Error 404: Not Found)
Traceback (most recent call last):
  File "/home/ubuntu/miniconda/envs/lns2+RL/lib/python3.11/site-packages/wandb/sdk/wandb_init.py", line 1170, in init
    run = wi.init()
          ^^^^^^^^^
  File "/home/ubuntu/miniconda/envs/lns2+RL/lib/python3.11/site-packages/wandb/sdk/wandb_init.py", line 781, in init
    raise error
wandb.errors.CommError: It appears that you do not have permission to access the requested resource. Please reach out to the project owner to grant you access. If you have the correct permissions, verify that there are no issues with your networking setup.(Error 404: Not Found)
2025-03-02 23:44:16,819 WARNING MsgRouterThr:533872 [router.py:message_loop():77] message_loop has been closed
