2025-03-02 23:38:48,695 INFO    StreamThr :532882 [internal.py:wandb_internal():86] W&B internal server running at pid: 532882, started at: 2025-03-02 23:38:48.694582
2025-03-02 23:38:48,700 DEBUG   HandlerThread:532882 [handler.py:handle_request():146] handle_request: status
2025-03-02 23:38:48,702 INFO    WriterThread:532882 [datastore.py:open_for_write():85] open: /home/ubuntu/LNS2-RL/wandb/run-20250302_233848-dpiokw9y/run-dpiokw9y.wandb
2025-03-02 23:38:48,702 DEBUG   SenderThread:532882 [sender.py:send():382] send: header
2025-03-02 23:38:48,705 DEBUG   SenderThread:532882 [sender.py:send():382] send: run
2025-03-02 23:38:48,716 INFO    SenderThread:532882 [sender.py:_maybe_setup_resume():763] checking resume status for your_name/MAPF/dpiokw9y
2025-03-02 23:38:49,157 ERROR   SenderThread:532882 [internal_api.py:execute():373] 404 response executing GraphQL.
2025-03-02 23:38:49,157 ERROR   SenderThread:532882 [internal_api.py:execute():374] {"errors":[{"message":"entity your_name not found during upsertBucket","path":["upsertBucket"]}],"data":{"upsertBucket":null}}
2025-03-02 23:38:49,157 ERROR   SenderThread:532882 [sender.py:send_run():987] It appears that you do not have permission to access the requested resource. Please reach out to the project owner to grant you access. If you have the correct permissions, verify that there are no issues with your networking setup.(Error 404: Not Found)
Traceback (most recent call last):
  File "/home/ubuntu/miniconda/envs/lns2+RL/lib/python3.11/site-packages/wandb/sdk/lib/retry.py", line 131, in __call__
    result = self._call_fn(*args, **kwargs)
             ^^^^^^^^^^^^^^^^^^^^^^^^^^^^^^
  File "/home/ubuntu/miniconda/envs/lns2+RL/lib/python3.11/site-packages/wandb/sdk/internal/internal_api.py", line 369, in execute
    return self.client.execute(*args, **kwargs)  # type: ignore
           ^^^^^^^^^^^^^^^^^^^^^^^^^^^^^^^^^^^^
  File "/home/ubuntu/miniconda/envs/lns2+RL/lib/python3.11/site-packages/wandb/vendor/gql-0.2.0/wandb_gql/client.py", line 52, in execute
    result = self._get_result(document, *args, **kwargs)
             ^^^^^^^^^^^^^^^^^^^^^^^^^^^^^^^^^^^^^^^^^^^
  File "/home/ubuntu/miniconda/envs/lns2+RL/lib/python3.11/site-packages/wandb/vendor/gql-0.2.0/wandb_gql/client.py", line 60, in _get_result
    return self.transport.execute(document, *args, **kwargs)
           ^^^^^^^^^^^^^^^^^^^^^^^^^^^^^^^^^^^^^^^^^^^^^^^^^
  File "/home/ubuntu/miniconda/envs/lns2+RL/lib/python3.11/site-packages/wandb/sdk/lib/gql_request.py", line 59, in execute
    request.raise_for_status()
  File "/home/ubuntu/miniconda/envs/lns2+RL/lib/python3.11/site-packages/requests/models.py", line 1024, in raise_for_status
    raise HTTPError(http_error_msg, response=self)
requests.exceptions.HTTPError: 404 Client Error: Not Found for url: https://api.wandb.ai/graphql

During handling of the above exception, another exception occurred:

Traceback (most recent call last):
  File "/home/ubuntu/miniconda/envs/lns2+RL/lib/python3.11/site-packages/wandb/sdk/internal/sender.py", line 985, in send_run
    self._init_run(run, config_value_dict)
  File "/home/ubuntu/miniconda/envs/lns2+RL/lib/python3.11/site-packages/wandb/sdk/internal/sender.py", line 1027, in _init_run
    server_run, inserted, server_messages = self._api.upsert_run(
                                            ^^^^^^^^^^^^^^^^^^^^^
  File "/home/ubuntu/miniconda/envs/lns2+RL/lib/python3.11/site-packages/wandb/apis/normalize.py", line 73, in wrapper
    raise err
  File "/home/ubuntu/miniconda/envs/lns2+RL/lib/python3.11/site-packages/wandb/apis/normalize.py", line 41, in wrapper
    return func(*args, **kwargs)
           ^^^^^^^^^^^^^^^^^^^^^
  File "/home/ubuntu/miniconda/envs/lns2+RL/lib/python3.11/site-packages/wandb/sdk/internal/internal_api.py", line 2212, in upsert_run
    response = self.gql(
               ^^^^^^^^^
  File "/home/ubuntu/miniconda/envs/lns2+RL/lib/python3.11/site-packages/wandb/sdk/internal/internal_api.py", line 341, in gql
    ret = self._retry_gql(
          ^^^^^^^^^^^^^^^^
  File "/home/ubuntu/miniconda/envs/lns2+RL/lib/python3.11/site-packages/wandb/sdk/lib/retry.py", line 147, in __call__
    retry_timedelta_triggered = check_retry_fn(e)
                                ^^^^^^^^^^^^^^^^^
  File "/home/ubuntu/miniconda/envs/lns2+RL/lib/python3.11/site-packages/wandb/util.py", line 965, in check_retry_fn
    return fallback_retry_fn(e)
           ^^^^^^^^^^^^^^^^^^^^
  File "/home/ubuntu/miniconda/envs/lns2+RL/lib/python3.11/site-packages/wandb/util.py", line 907, in no_retry_auth
    raise CommError(
wandb.errors.CommError: It appears that you do not have permission to access the requested resource. Please reach out to the project owner to grant you access. If you have the correct permissions, verify that there are no issues with your networking setup.(Error 404: Not Found)
2025-03-02 23:38:49,357 DEBUG   HandlerThread:532882 [handler.py:handle_request():146] handle_request: shutdown
2025-03-02 23:38:49,357 INFO    HandlerThread:532882 [handler.py:finish():866] shutting down handler
2025-03-02 23:38:49,705 INFO    WriterThread:532882 [datastore.py:close():294] close: /home/ubuntu/LNS2-RL/wandb/run-20250302_233848-dpiokw9y/run-dpiokw9y.wandb
2025-03-02 23:38:50,262 INFO    SenderThread:532882 [sender.py:finish():1548] shutting down sender
