2025-03-02 23:41:44,864 INFO    StreamThr :533725 [internal.py:wandb_internal():86] W&B internal server running at pid: 533725, started at: 2025-03-02 23:41:44.862950
2025-03-02 23:41:44,867 DEBUG   HandlerThread:533725 [handler.py:handle_request():146] handle_request: status
2025-03-02 23:41:44,871 INFO    WriterThread:533725 [datastore.py:open_for_write():85] open: /home/ubuntu/LNS2-RL/wandb/run-20250302_234144-z7qam1n3/run-z7qam1n3.wandb
2025-03-02 23:41:44,871 DEBUG   SenderThread:533725 [sender.py:send():382] send: header
2025-03-02 23:41:44,872 DEBUG   SenderThread:533725 [sender.py:send():382] send: run
2025-03-02 23:41:44,882 INFO    SenderThread:533725 [sender.py:_maybe_setup_resume():763] checking resume status for your_name/MAPF/z7qam1n3
2025-03-02 23:41:45,318 ERROR   SenderThread:533725 [internal_api.py:execute():373] 404 response executing GraphQL.
2025-03-02 23:41:45,318 ERROR   SenderThread:533725 [internal_api.py:execute():374] {"errors":[{"message":"entity your_name not found during upsertBucket","path":["upsertBucket"]}],"data":{"upsertBucket":null}}
2025-03-02 23:41:45,318 ERROR   SenderThread:533725 [sender.py:send_run():987] It appears that you do not have permission to access the requested resource. Please reach out to the project owner to grant you access. If you have the correct permissions, verify that there are no issues with your networking setup.(Error 404: Not Found)
Traceback (most recent call last):
  File "/home/ubuntu/miniconda/envs/lns2+RL/lib/python3.11/site-packages/wandb/sdk/lib/retry.py", line 131, in __call__
    result = self._call_fn(*args, **kwargs)
             ^^^^^^^^^^^^^^^^^^^^^^^^^^^^^^
  File "/home/ubuntu/miniconda/envs/lns2+RL/lib/python3.11/site-packages/wandb/sdk/internal/internal_api.py", line 369, in execute
    return self.client.execute(*args, **kwargs)  # type: ignore
           ^^^^^^^^^^^^^^^^^^^^^^^^^^^^^^^^^^^^
  File "/home/ubuntu/miniconda/envs/lns2+RL/lib/python3.11/site-packages/wandb/vendor/gql-0.2.0/wandb_gql/client.py", line 52, in execute
    result = self._get_result(document, *args, **kwargs)
             ^^^^^^^^^^^^^^^^^^^^^^^^^^^^^^^^^^^^^^^^^^^
  File "/home/ubuntu/miniconda/envs/lns2+RL/lib/python3.11/site-packages/wandb/vendor/gql-0.2.0/wandb_gql/client.py", line 60, in _get_result
    return self.transport.execute(document, *args, **kwargs)
           ^^^^^^^^^^^^^^^^^^^^^^^^^^^^^^^^^^^^^^^^^^^^^^^^^
  File "/home/ubuntu/miniconda/envs/lns2+RL/lib/python3.11/site-packages/wandb/sdk/lib/gql_request.py", line 59, in execute
    request.raise_for_status()
  File "/home/ubuntu/miniconda/envs/lns2+RL/lib/python3.11/site-packages/requests/models.py", line 1024, in raise_for_status
    raise HTTPError(http_error_msg, response=self)
requests.exceptions.HTTPError: 404 Client Error: Not Found for url: https://api.wandb.ai/graphql

During handling of the above exception, another exception occurred:

Traceback (most recent call last):
  File "/home/ubuntu/miniconda/envs/lns2+RL/lib/python3.11/site-packages/wandb/sdk/internal/sender.py", line 985, in send_run
    self._init_run(run, config_value_dict)
  File "/home/ubuntu/miniconda/envs/lns2+RL/lib/python3.11/site-packages/wandb/sdk/internal/sender.py", line 1027, in _init_run
    server_run, inserted, server_messages = self._api.upsert_run(
                                            ^^^^^^^^^^^^^^^^^^^^^
  File "/home/ubuntu/miniconda/envs/lns2+RL/lib/python3.11/site-packages/wandb/apis/normalize.py", line 73, in wrapper
    raise err
  File "/home/ubuntu/miniconda/envs/lns2+RL/lib/python3.11/site-packages/wandb/apis/normalize.py", line 41, in wrapper
    return func(*args, **kwargs)
           ^^^^^^^^^^^^^^^^^^^^^
  File "/home/ubuntu/miniconda/envs/lns2+RL/lib/python3.11/site-packages/wandb/sdk/internal/internal_api.py", line 2212, in upsert_run
    response = self.gql(
               ^^^^^^^^^
  File "/home/ubuntu/miniconda/envs/lns2+RL/lib/python3.11/site-packages/wandb/sdk/internal/internal_api.py", line 341, in gql
    ret = self._retry_gql(
          ^^^^^^^^^^^^^^^^
  File "/home/ubuntu/miniconda/envs/lns2+RL/lib/python3.11/site-packages/wandb/sdk/lib/retry.py", line 147, in __call__
    retry_timedelta_triggered = check_retry_fn(e)
                                ^^^^^^^^^^^^^^^^^
  File "/home/ubuntu/miniconda/envs/lns2+RL/lib/python3.11/site-packages/wandb/util.py", line 965, in check_retry_fn
    return fallback_retry_fn(e)
           ^^^^^^^^^^^^^^^^^^^^
  File "/home/ubuntu/miniconda/envs/lns2+RL/lib/python3.11/site-packages/wandb/util.py", line 907, in no_retry_auth
    raise CommError(
wandb.errors.CommError: It appears that you do not have permission to access the requested resource. Please reach out to the project owner to grant you access. If you have the correct permissions, verify that there are no issues with your networking setup.(Error 404: Not Found)
2025-03-02 23:41:45,444 DEBUG   HandlerThread:533725 [handler.py:handle_request():146] handle_request: shutdown
2025-03-02 23:41:45,444 INFO    HandlerThread:533725 [handler.py:finish():866] shutting down handler
2025-03-02 23:41:45,872 INFO    WriterThread:533725 [datastore.py:close():294] close: /home/ubuntu/LNS2-RL/wandb/run-20250302_234144-z7qam1n3/run-z7qam1n3.wandb
2025-03-02 23:41:46,323 INFO    SenderThread:533725 [sender.py:finish():1548] shutting down sender
